try:
    print("inside try")

except TypeError:
    print("inside except")
